<mujoco model="rm65 + inspire right hand">
  <compiler angle="radian"/>

  <statistic center="0 0 0.4" extent="1"/>

  <option integrator="implicitfast" cone="elliptic" impratio="10"/>

  <visual>
    <headlight diffuse="0.6 0.6 0.6" ambient="0.3 0.3 0.3" specular="0 0 0"/>
    <rgba haze="0.15 0.25 0.35 1"/>
    <global azimuth="-45" elevation="-20"/>
  </visual>

  <default>
    <default class="rm65">
      <default class="rm65/visual">
        <geom type="mesh" contype="0" conaffinity="0" group="2" rgba="0.82 0.82 0.82 1"/>
      </default>
      <default class="rm65/collision">
        <geom type="mesh" group="3"/>
      </default>
      <default class="rm65_actuator">
        <position kp="150" kv="40" forcerange="-100 100"/>
      </default>
    </default>

    <default class="inspire_hand">
      <joint damping="0.05"/>
      <position kp="3" dampratio="1"/>
      <geom density="800"/>
      <default class="inspire_hand/visual">
        <geom type="mesh" contype="0" conaffinity="0" group="2" rgba="0.65 0.65 0.65 1"/>
      </default>
    </default>

    <site size="0.001" rgba="0.5 0.5 0.5 0.3" group="4"/>
  </default>

  <asset>
    <texture type="skybox" builtin="gradient" rgb1="0.6 0.6 0.6" rgb2="0 0 0" width="512" height="3072"/>
    <texture type="2d" name="groundplane" builtin="checker" mark="edge" rgb1="0.5 0.5 0.5" rgb2="0.3 0.3 0.3"
      markrgb="0.4 0.4 0.4" width="300" height="300"/>
    <material name="groundplane" texture="groundplane" texuniform="true" texrepeat="5 5" reflectance="0.2"/>

    <!-- RM65 arm meshes -->
    <mesh name="rm65_base_link" file="../../third_party/rm_models/RM65/urdf/RM65-6F/meshes/base_link.STL"/>
    <mesh name="rm65_link_1"    file="../../third_party/rm_models/RM65/urdf/RM65-6F/meshes/link_1.STL"/>
    <mesh name="rm65_link_2"    file="../../third_party/rm_models/RM65/urdf/RM65-6F/meshes/link_2.STL"/>
    <mesh name="rm65_link_3"    file="../../third_party/rm_models/RM65/urdf/RM65-6F/meshes/link_3.STL"/>
    <mesh name="rm65_link_4"    file="../../third_party/rm_models/RM65/urdf/RM65-6F/meshes/link_4.STL"/>
    <mesh name="rm65_link_5"    file="../../third_party/rm_models/RM65/urdf/RM65-6F/meshes/link_5.STL"/>
    <mesh name="rm65_link_6"    file="../../third_party/rm_models/RM65/urdf/RM65-6F/meshes/link_6.STL"/>

    <!-- Inspire RH56DFX right hand meshes -->
    <mesh name="inspire_base_link"             file="../../third_party/AnyDexRetarget/assets/inspire_hand/meshes/mujoco_stl/right_base_link.stl"/>
    <mesh name="inspire_thumb_proximal_base"   file="../../third_party/AnyDexRetarget/assets/inspire_hand/meshes/mujoco_stl/right_thumb_proximal_base.stl"/>
    <mesh name="inspire_thumb_proximal"        file="../../third_party/AnyDexRetarget/assets/inspire_hand/meshes/mujoco_stl/right_thumb_proximal.stl"/>
    <mesh name="inspire_thumb_intermediate"    file="../../third_party/AnyDexRetarget/assets/inspire_hand/meshes/mujoco_stl/right_thumb_intermediate.stl"/>
    <mesh name="inspire_thumb_distal"          file="../../third_party/AnyDexRetarget/assets/inspire_hand/meshes/mujoco_stl/right_thumb_distal.stl"/>
    <mesh name="inspire_index_proximal"        file="../../third_party/AnyDexRetarget/assets/inspire_hand/meshes/mujoco_stl/right_index_proximal.stl"/>
    <mesh name="inspire_index_intermediate"    file="../../third_party/AnyDexRetarget/assets/inspire_hand/meshes/mujoco_stl/right_index_intermediate.stl"/>
    <mesh name="inspire_middle_intermediate"   file="../../third_party/AnyDexRetarget/assets/inspire_hand/meshes/mujoco_stl/right_middle_intermediate.stl"/>
    <mesh name="inspire_pinky_intermediate"    file="../../third_party/AnyDexRetarget/assets/inspire_hand/meshes/mujoco_stl/right_pinky_intermediate.stl"/>
  </asset>

  <worldbody>
    <light pos="0 0 1.5" dir="0 0 -1" directional="true"/>
    <geom name="floor" size="0 0 0.05" type="plane" material="groundplane"/>

    <body name="base_link" pos="0 0 0" childclass="rm65">
      <geom class="rm65/visual" mesh="rm65_base_link"/>
      <geom class="rm65/collision" mesh="rm65_base_link"/>

      <body name="link_1" pos="0 0 0.2405">
        <joint name="joint_1" type="hinge" axis="0 0 1" range="-3.106 3.106"/>
        <geom class="rm65/visual" mesh="rm65_link_1"/>
        <geom class="rm65/collision" mesh="rm65_link_1"/>

        <body name="link_2" pos="0 0 0" quat="0.499998 0.500000 -0.500000 0.500002">
          <joint name="joint_2" type="hinge" axis="0 0 1" range="-2.2689 2.2689"/>
          <geom class="rm65/visual" mesh="rm65_link_2"/>
          <geom class="rm65/collision" mesh="rm65_link_2"/>

          <body name="link_3" pos="0.256 0 0" quat="0.707105 0 0 0.707108">
            <joint name="joint_3" type="hinge" axis="0 0 1" range="-2.356 2.356"/>
            <geom class="rm65/visual" mesh="rm65_link_3"/>
            <geom class="rm65/collision" mesh="rm65_link_3"/>

            <body name="link_4" pos="0 -0.21 0" quat="0.707105 0.707108 0 0">
              <joint name="joint_4" type="hinge" axis="0 0 1" range="-3.106 3.106"/>
              <geom class="rm65/visual" mesh="rm65_link_4"/>
              <geom class="rm65/collision" mesh="rm65_link_4"/>

              <body name="link_5" pos="0 0 0" quat="0.707105 -0.707108 0 0">
                <joint name="joint_5" type="hinge" axis="0 0 1" range="-2.234 2.234"/>
                <geom class="rm65/visual" mesh="rm65_link_5"/>
                <geom class="rm65/collision" mesh="rm65_link_5"/>

                <body name="link_6" pos="0 -0.1725 0" quat="0.707105 0.707108 0 0">
                  <joint name="joint_6" type="hinge" axis="0 0 1" range="-6.28 6.28"/>
                  <geom class="rm65/visual" mesh="rm65_link_6"/>
                  <geom class="rm65/collision" mesh="rm65_link_6"/>

                  <!-- EE site (wrist reference for IK) -->
                  <site name="rm65_ee_site" pos="0 0 0.05" quat="1 0 0 0"/>

                  <!-- Inspire RH56DFX right hand
                       Mounted on RM65 flange: +Z of flange = palm normal outward.
                       The inspire_hand_right_mujoco.xml palm body has a base_joint
                       rotation baked in (rpy="-1.57079 0 3.14159"), so we compensate
                       here with quat to align palm facing forward (+X of link_6). -->
                  <body name="palm" pos="0 0 0"
                        quat="-1 1 0 0"
                        childclass="inspire_hand">
                    <geom type="mesh" mesh="inspire_base_link" class="inspire_hand/visual"/>

                    <body name="thumb_proximal_base" pos="-0.01696 -0.0691 -0.02045" quat="0.499998 0.500000 -0.500000 0.500002">
                      <joint name="thumb_proximal_yaw_joint" axis="0 0 -1" range="0 1.308"/>
                      <geom type="mesh" mesh="inspire_thumb_proximal_base" class="inspire_hand/visual"/>
                      <body name="thumb_proximal" pos="-0.0088099 0.010892 -0.00925" quat="0.099684 0.099685 0.700046 0.700044">
                        <joint name="thumb_proximal_pitch_joint" axis="0 0 1" range="0 0.6"/>
                        <geom type="mesh" mesh="inspire_thumb_proximal" class="inspire_hand/visual"/>
                        <body name="thumb_intermediate" pos="0.04407 0.034553 -0.0008">
                          <joint name="thumb_intermediate_joint" axis="0 0 1" range="0 0.8"/>
                          <geom type="mesh" mesh="inspire_thumb_intermediate" class="inspire_hand/visual"/>
                          <body name="thumb_distal" pos="0.020248 0.010156 -0.0012">
                            <joint name="thumb_distal_joint" axis="0 0 1" range="0 0.4"/>
                            <geom type="mesh" mesh="inspire_thumb_distal" class="inspire_hand/visual"/>
                          </body>
                        </body>
                      </body>
                    </body>

                    <body name="index_proximal" pos="0.00028533 -0.13653 -0.032268" quat="0.017445 -0.999848 0.000000 0.000000">
                      <joint name="index_proximal_joint" axis="0 0 1" range="0 1.47"/>
                      <geom type="mesh" mesh="inspire_index_proximal" class="inspire_hand/visual"/>
                      <body name="index_intermediate" pos="-0.0026138 0.032026 -0.001">
                        <joint name="index_intermediate_joint" axis="0 0 1" range="-0.04545 1.56"/>
                        <geom type="mesh" mesh="inspire_index_intermediate" class="inspire_hand/visual"/>
                      </body>
                    </body>

                    <body name="middle_proximal" pos="0.00028533 -0.1371 -0.01295" quat="-0.000004 -1.000000 0.000000 0.000000">
                      <joint name="middle_proximal_joint" axis="0 0 1" range="0 1.47"/>
                      <geom type="mesh" mesh="inspire_index_proximal" class="inspire_hand/visual"/>
                      <body name="middle_intermediate" pos="-0.0024229 0.032041 -0.001">
                        <joint name="middle_intermediate_joint" axis="0 0 1" range="-0.04545 1.56"/>
                        <geom type="mesh" mesh="inspire_middle_intermediate" class="inspire_hand/visual"/>
                      </body>
                    </body>

                    <body name="ring_proximal" pos="0.00028533 -0.13691 0.0062872" quat="0.026193 0.999657 0.000000 0.000000">
                      <joint name="ring_proximal_joint" axis="0 0 1" range="0 1.47"/>
                      <geom type="mesh" mesh="inspire_index_proximal" class="inspire_hand/visual"/>
                      <body name="ring_intermediate" pos="-0.0024229 0.032041 -0.001">
                        <joint name="ring_intermediate_joint" axis="0 0 1" range="-0.04545 1.56"/>
                        <geom type="mesh" mesh="inspire_index_intermediate" class="inspire_hand/visual"/>
                      </body>
                    </body>

                    <body name="pinky_proximal" pos="0.00028533 -0.13571 0.025488" quat="0.052322 0.998630 0.000000 0.000000">
                      <joint name="pinky_proximal_joint" axis="0 0 1" range="0 1.47"/>
                      <geom type="mesh" mesh="inspire_index_proximal" class="inspire_hand/visual"/>
                      <body name="pinky_intermediate" pos="-0.0024229 0.032041 -0.001">
                        <joint name="pinky_intermediate_joint" axis="0 0 1" range="-0.04545 1.56"/>
                        <geom type="mesh" mesh="inspire_pinky_intermediate" class="inspire_hand/visual"/>
                      </body>
                    </body>
                  </body>

                  <camera name="wrist_cam" pos="0 0.05 0.0" euler="3.14159 0 0" fovy="70"/>
                </body>
              </body>
            </body>
          </body>
        </body>
      </body>
    </body>

    <camera name="scene_cam" pos="1.2 -0.8 0.9" xyaxes="0.6 0.8 0 -0.3 0.22 0.9" fovy="45"/>
  </worldbody>

  <actuator>
    <!-- RM65 arm (6 DOF) -->
    <position class="rm65_actuator" name="joint_1" joint="joint_1" ctrlrange="-3.106 3.106"/>
    <position class="rm65_actuator" name="joint_2" joint="joint_2" ctrlrange="-2.2689 2.2689"/>
    <position class="rm65_actuator" name="joint_3" joint="joint_3" ctrlrange="-2.356 2.356"/>
    <position class="rm65_actuator" name="joint_4" joint="joint_4" ctrlrange="-3.106 3.106"/>
    <position class="rm65_actuator" name="joint_5" joint="joint_5" ctrlrange="-2.234 2.234"/>
    <position class="rm65_actuator" name="joint_6" joint="joint_6" ctrlrange="-6.28 6.28"/>
    <!-- Inspire RH56DFX right hand (12 DOF) -->
    <position class="inspire_hand" name="thumb_proximal_yaw"   joint="thumb_proximal_yaw_joint"   ctrlrange="0 1.308"/>
    <position class="inspire_hand" name="thumb_proximal_pitch" joint="thumb_proximal_pitch_joint" ctrlrange="0 0.6"/>
    <position class="inspire_hand" name="thumb_intermediate"   joint="thumb_intermediate_joint"   ctrlrange="0 0.8"/>
    <position class="inspire_hand" name="thumb_distal"         joint="thumb_distal_joint"         ctrlrange="0 0.4"/>
    <position class="inspire_hand" name="index_proximal"       joint="index_proximal_joint"       ctrlrange="0 1.47"/>
    <position class="inspire_hand" name="index_intermediate"   joint="index_intermediate_joint"   ctrlrange="-0.04545 1.56"/>
    <position class="inspire_hand" name="middle_proximal"      joint="middle_proximal_joint"      ctrlrange="0 1.47"/>
    <position class="inspire_hand" name="middle_intermediate"  joint="middle_intermediate_joint"  ctrlrange="-0.04545 1.56"/>
    <position class="inspire_hand" name="ring_proximal"        joint="ring_proximal_joint"        ctrlrange="0 1.47"/>
    <position class="inspire_hand" name="ring_intermediate"    joint="ring_intermediate_joint"    ctrlrange="-0.04545 1.56"/>
    <position class="inspire_hand" name="pinky_proximal"       joint="pinky_proximal_joint"       ctrlrange="0 1.47"/>
    <position class="inspire_hand" name="pinky_intermediate"   joint="pinky_intermediate_joint"   ctrlrange="-0.04545 1.56"/>
  </actuator>
  <keyframe>
    <key name="home" qpos="0 -0.522 -1.81 0.0099 0.782 0  0 0 0 0 0 0 0 0 0 0 0 0"/>
  </keyframe>

</mujoco>
